Workbook
Name CodingRules: Guide!$A$165
Name CreateNewProject: Guide!$A$99
Name InstallIAR: Guide!$A$3

Sheet Agenda
B1: MARQUARDT SUMMER INTERNSHIP 2024
B2: Summer Session starts on July 1, 2024 and ends on July 19, 2024.
B3: Each participant will receive a hardware super-kit comprising:
C4: - 1x Development Board Kit comprising:
D5: - 1x ATmega324PB development board
D6: - 1x IO extension board
D7: - 1x OLED extension board
D8: - 1x USB cable (type micro-B)
C9: - 1x Logic Analyzer Kit comprising:
D10: - 1x Logic Analyzer box
D11: - 1x USB cable (type C)
D12: - 5x wires mother-mother
B13: Please return the hardware super-kit at the end of the Internship! Synch-up with your instructor to receive and return the super-kit!
B15: Workflow | AO15: Tools
B16: Below you have a sketch of our main workflow: | AO16: Below you have a checklist with infrastructure tools/environments used:
AP19: Item | AW19: Expected status
AO20: FALSE | AP20: Whatsapp group | AW20: created & joined
AO21: FALSE | AP21: Google Meet room | AW21: created & having access code
AO22: FALSE | AP22: Dev board kit handover | AW22: received & functional
AO23: FALSE | AP23: IAR Embedded Workbench | AW23: downloaded & installed with 4K trial license
AO24: FALSE | AP24: Google Sheets | AW24: access granted to Work Instructions/Progress
AO25: FALSE | AP25: Github | AS25: FALSE | AT25: server | AW25: account created & access granted
AS26: FALSE | AT26: desktop | AW26: downloaded & installed
AW27: GitHub Desktop App
T28: Upload Project/ `git push`
AF29: quizzes
AF30: reference-documents
AF31: work-instructions
AF32: src
J33: Coding......
S34: Download Reference Documents
U35: Low-stake quizzes
P41: Meetings/ discussions/ Q&A
B47: Project organization
C48: Each participant will organize the project on his local computer under the following mandatory folder structure (Please respect the C:/ path shown below! Do not change it!).
C49: First step: create the following directory
C50: C:/ | E50: MQ_Summer_Internship_2024
C52: Then, in a second step, when you will download from github the repositories, you will save them under the above directory. Therefore the folder structure will finally look like this:
C54: C:/ | E54: MQ_Summer_Internship_2024
F55: Project
...

Sheet Guide
B1: MARQUARDT SUMMER INTERNSHIP 2024
B2: Guidelines on how to install IAR Embedded Workbench IDE + creating a new project
B3: How to install IAR Embedded Workbench IDE
C4: Go to IAR website and choose the product as in the picture below:
C24: Then scroll down the page to the supported architectures and choose AVR:
C40: Then go down the page until you encounter the trial version box.
C63: Download the trial version and install the latest package version. You will be asked to introduce a license number: choose to get an evaluation license and register yourself on the IAR’s website as below:
C64: Be attentive !!! to choose 4K code size !!! version of the evaluation license !!!
C96: You will get by email a license code which you will use further.
C97: Now you are ready to start a new project with IAR Embedded Workbench!
B99: How to create a new project
C100: Follow the steps below:
C101: 1 | D101: Connect the main ATMega324PB board via USB to your PC/laptop.
D102: Green LED (Power) should be lit.
C103: 2 | D103: Open IAR Embedded Workbench IDE.
C104: 3 | D104: From menu bar create a new project IAR:
D105: Project -> Create New Project -> C -> main -> OK
C126: 4 | D126: Save the project with the following name SpringInternship2023 (observe the file extension is .ewp). Save it to Project folder.
C127: 5 | D127: Save the workspace: File -> Save All then choose a name for it as the following
D128: pattern shows (e.g. StanC) (observe the file extension is now .eww). The difference
D129: between project and workspace is that a workspace can hold many other projects.
C130: 6 | D130: Further on, there are three settings you have to make: choose the microcontroller type and the debugger type and finally shutdown compiler optimizations.
D139: First, right click on project name in the Project browser -> Options -> General Options -> Target -> Processor Configuration -> ATmega324PB
D140: (look on the development board and visually check you have indeed the ATmega324PB!!!).
D141: Second option is on Debugger area, where you select Atmel-ICE from the drop-down list (attention!!! DO NOT select SIMULATOR!!!). Confirm with OK.
D161: Third, go to C/C++ Compiler -> (tab) Optimizations -> Level -> None.
C163: 7 | D163: That's it! this is all you need to get started on writing code, downloading, run it and/or debugging.
B165: Coding rules
C167: 1 | D167: comment your code at each line (relevant line & relevant comment)
C168: 2 | D168: one exercise = one commit on github
C169: 3 | D169: place a comment at the beginning of the file showing what exercise is it (USE 123 SCHEMATIC)
C170: 4 | D170: upload on github only compilable & runable code!!! full project (all files included) | L170: FOR YOUR INFO | M170: 🔊
C171: 5 | D171: no use of magic numbers (use #defines instead) | L171: Smelly code and Magic Numbers - YouTube
C172: 6 | D172: use #include " " for your own modules, not < >
C173: 7 | D173: start to name your functions and variables with a prefix of the module
E174: e.g. tc0 is my module
F175: => tc0_init( ), tc0_set_value( ) are functions
F176: => tc0_counter, tc0_temp are variables
B178: How to work with LOGIC ANALYZER (example for LED0 exercise)
C180: 1 | D180: Cables connection must be done when the analyzer is NOT POWERED!!!
...

Sheet MyProgress
B1: MARQUARDT SUMMER INTERNSHIP 2024
B3: Your progress | F3: =SUM(F6,L6,R6,X6,AD6,F17,L17)/7 -> 0 | G3: =IFERROR(__xludf.DUMMYFUNCTION("SPARKLINE(F3,{""charttype"",""bar"";""max"",1})"),"")
B6: Week 1 | F6: ='W1-part1'!K2 -> 0 | H6: Week 2 | L6: ='W1-part2'!K2 -> 0 | N6: Week 3 | R6: ='W2-part1'!K2 -> 0
B7: Obj 1 | C7: ='W1-part1'!B11 -> 🥇 | D7: ='W1-part1'!C11 -> 0 | E7: =IFERROR(__xludf.DUMMYFUNCTION("SPARKLINE(D7,{""charttype"",""bar"";""max"",1;""min"",0;""color1"",IF(D7>0.75,""green"",IF(D7>0.5,""yellow"",""red""))})"),"") | H7: Obj 1 | I7: 🥇 | J7: ='W1-part2'!C12 -> 0 | K7: =IFERROR(__xludf.DUMMYFUNCTION("SPARKLINE(J7,{""charttype"",""bar"";""max"",1;""min"",0;""color1"",IF(J7>0.75,""green"",IF(J7>0.5,""yellow"",""red""))})"),"") | N7: Obj 1 | O7: 🥇 | P7: ='W2-part1'!C13 -> 0 | Q7: =IFERROR(__xludf.DUMMYFUNCTION("SPARKLINE(P7,{""charttype"",""bar"";""max"",1;""min"",0;""color1"",IF(P7>0.75,""green"",IF(P7>0.5,""yellow"",""red""))})"),"")
B8: Obj 2 | C8: 🥇 | D8: ='W1-part1'!C34 -> 0 | E8: =IFERROR(__xludf.DUMMYFUNCTION("SPARKLINE(D8,{""charttype"",""bar"";""max"",1;""min"",0;""color1"",IF(D8>0.75,""green"",IF(D8>0.5,""yellow"",""red""))})"),"") | H8: Obj 2 | I8: 🥇 | J8: ='W1-part2'!C36 -> 0 | K8: =IFERROR(__xludf.DUMMYFUNCTION("SPARKLINE(J8,{""charttype"",""bar"";""max"",1;""min"",0;""color1"",IF(J8>0.75,""green"",IF(J8>0.5,""yellow"",""red""))})"),"") | N8: Obj 2 | O8: 🥇 | P8: ='W2-part1'!C64 -> 0 | Q8: =IFERROR(__xludf.DUMMYFUNCTION("SPARKLINE(P8,{""charttype"",""bar"";""max"",1;""min"",0;""color1"",IF(P8>0.75,""green"",IF(P8>0.5,""yellow"",""red""))})"),"")
B9: Obj 3 | C9: 🥇 | D9: ='W1-part1'!C47 -> 0 | E9: =IFERROR(__xludf.DUMMYFUNCTION("SPARKLINE(D9,{""charttype"",""bar"";""max"",1;""min"",0;""color1"",IF(D9>0.75,""green"",IF(D9>0.5,""yellow"",""red""))})"),"") | H9: Obj 3 | I9: 🥇 | J9: ='W1-part2'!C71 -> 0 | K9: =IFERROR(__xludf.DUMMYFUNCTION("SPARKLINE(J9,{""charttype"",""bar"";""max"",1;""min"",0;""color1"",IF(J9>0.75,""green"",IF(J9>0.5,""yellow"",""red""))})"),"") | N9: Obj 3 | O9: 🥇 | P9: ='W2-part1'!C89 -> 0 | Q9: =IFERROR(__xludf.DUMMYFUNCTION("SPARKLINE(P9,{""charttype"",""bar"";""max"",1;""min"",0;""color1"",IF(P9>0.75,""green"",IF(P9>0.5,""yellow"",""red""))})"),"")
B10: Obj 4 | C10: 🥇 | D10: ='W1-part1'!C61 -> 0 | E10: =IFERROR(__xludf.DUMMYFUNCTION("SPARKLINE(D10,{""charttype"",""bar"";""max"",1;""min"",0;""color1"",IF(D10>0.75,""green"",IF(D10>0.5,""yellow"",""red""))})"),"") | H10: Obj 4 | I10: 🥇 | J10: ='W1-part2'!C89 -> 0 | K10: =IFERROR(__xludf.DUMMYFUNCTION("SPARKLINE(J10,{""charttype"",""bar"";""max"",1;""min"",0;""color1"",IF(J10>0.75,""green"",IF(J10>0.5,""yellow"",""red""))})"),"") | N10: Obj 4 | O10: 🥇 | P10: ='W2-part1'!C113 -> 0 | Q10: =IFERROR(__xludf.DUMMYFUNCTION("SPARKLINE(P10,{""charttype"",""bar"";""max"",1;""min"",0;""color1"",IF(P10>0.75,""green"",IF(P10>0.5,""yellow"",""red""))})"),"")
B11: Obj 5 | C11: 🥇 | D11: ='W1-part1'!C92 -> 0 | E11: =IFERROR(__xludf.DUMMYFUNCTION("SPARKLINE(D11,{""charttype"",""bar"";""max"",1;""min"",0;""color1"",IF(D11>0.75,""green"",IF(D11>0.5,""yellow"",""red""))})"),"") | H11: Obj 5 | I11: 🥇 | J11: ='W1-part2'!C150 -> 0 | K11: =IFERROR(__xludf.DUMMYFUNCTION("SPARKLINE(J11,{""charttype"",""bar"";""max"",1;""min"",0;""color1"",IF(J11>0.75,""green"",IF(J11>0.5,""yellow"",""red""))})"),"") | N11: Obj 5 | O11: 🥇 | P11: ='W2-part1'!C148 -> 0 | Q11: =IFERROR(__xludf.DUMMYFUNCTION("SPARKLINE(P11,{""charttype"",""bar"";""max"",1;""min"",0;""color1"",IF(P11>0.75,""green"",IF(P11>0.5,""yellow"",""red""))})"),"")
B12: Obj 6 | C12: 🥇 | D12: ='W1-part1'!C177 -> 0 | E12: =IFERROR(__xludf.DUMMYFUNCTION("SPARKLINE(D12,{""charttype"",""bar"";""max"",1;""min"",0;""color1"",IF(D12>0.75,""green"",IF(D12>0.5,""yellow"",""red""))})"),"") | H12: Obj 6 | I12: 🥇 | J12: ='W1-part2'!C169 -> 0 | K12: =IFERROR(__xludf.DUMMYFUNCTION("SPARKLINE(J12,{""charttype"",""bar"";""max"",1;""min"",0;""color1"",IF(J12>0.75,""green"",IF(J12>0.5,""yellow"",""red""))})"),"") | N12: Obj 6 | O12: 🥇 | P12: ='W2-part1'!C220 -> 0 | Q12: =IFERROR(__xludf.DUMMYFUNCTION("SPARKLINE(P12,{""charttype"",""bar"";""max"",1;""min"",0;""color1"",IF(P12>0.75,""green"",IF(P12>0.5,""yellow"",""red""))})"),"")
B13: Obj 7 | C13: 🥇 | D13: ='W1-part1'!C254 -> 0 | E13: =IFERROR(__xludf.DUMMYFUNCTION("SPARKLINE(D13,{""charttype"",""bar"";""max"",1;""min"",0;""color1"",IF(D13>0.75,""green"",IF(D13>0.5,""yellow"",""red""))})"),"")

Sheet MyTests
B1: MARQUARDT SUMMER INTERNSHIP 2024
C2: Reference Score | D2: Your Current Score
A3: Week | B3: Test Link | C3: =SUM(C4:C6) -> 47 | D3: =SUM(D4:D6) -> 0 | F3: You are doing better than | G3: x | H3: % of your peers.
A4: 1 | B4: Review 1 | C4: 12
A5: 2 | B5: Review 2 | C5: 15
A6: 3 | B6: Review 3 | C6: 20

Sheet W1-part1
B1: MARQUARDT SUMMER INTERNSHIP 2024
B2: GOAL FOR THIS WEEK 1: set up the stage for software embedded development | K2: =SUM(C11,C34,C47,C61,C92,C177,C254)/7 -> 0 | M2: =COUNTIF(L13:L308,TRUE)/O2 -> 0 | N2: of | O2: =SUM(COUNTIF(L13:L308,TRUE),COUNTIF(L13:L308,FALSE)) -> 19 | P2: additional materials
C3: By the end of this week you should be able to recognize and control your system and tools very effectively and efficiently.
C4: Also you must be honest to yourself making an assessment for your knowledge/skill level from where you start to grow.
C5: On short what you will do this week:
D6: - get to know your dev boards, IDE and backend compiler.
D7: - refresh your knowledge on C programming language, microcontrollers and basic electronics
B10: Objective 1: Knowing your main development board (you can get help by opening also User Guide for ATMega324PB Xplained PRO)
B11: 🥇 | C11: =COUNTIF(D13:D24,TRUE)/COUNT(C13:C24) -> 0 | E11: =IFERROR(__xludf.DUMMYFUNCTION("SPARKLINE(C11,{""charttype"",""bar"";""max"",1;""min"",0;""color1"",IF(C11>0.75,""green"",IF(C11>0.5,""yellow"",""red""))})"),"")
C13: 111 | D13: FALSE | E13: Search and identify ATMega324PB microcontroller on the board.
C14: 112 | D14: FALSE | E14: Search and identify LED0, a LED that you will program to lit later
C15: 113 | D15: FALSE | E15: Search and identify SW0, a switch that you will program later to be interpreted as pressed/not pressed.
C16: 114 | D16: FALSE | E16: Search and identify other components like external oscillator and debugger chip/microcontroller.
C17: 115 | D17: FALSE | E17: How many extension headers there are on the board?
F18: ( <<< just fill in the number ) | M18: FOR YOUR INFO | P18: 🔊
C19: 116 | D19: FALSE | E19: How are the extension headers labeled? | M19: During internship you will develop embedded applications without using wires in circuits because the boards
F20: ( <<< one example of label found ) | M20: can be easily connected via built-in connectors. It is a safe practice, especially now that you are new
C21: 117 | D21: FALSE | E21: Search and identify GND and VCC pins on the headers and on the power connector. | M21: to embedded and PCB burn-outs should be avoided. But remember that in the office you will be often
C22: 118 | D22: FALSE | E22: Connect the USB cable to the main board and you should see the green LED lit. | M22: required to solder some wires on the PCB with all the necessary safety measures!
C24: 119 | D24: FALSE | E24: OPTIONAL | F24: Even though you don't have an external power supply connected to VCC and GND the board is still | M24: FOR YOUR INFO | P24: 🔊
F25: powered up (green LED lit) when pluging in the USB cable. How can you explain that? | M25: You can watch/read on about Human-Body Model used in electrostatic discharges here:
G26: (<<< your answer here) | L26: FALSE | M26: Understanding Electrostatic Discharge (ESD) for Technicians - YouTube | S26: 😂👍
L27: FALSE | M27: What is ESD? Learn more about the basics of electrostatic charge - YouTube
L28: FALSE | M28: Human-body model - Wikipedia
L29: FALSE | M29: Human-Body Model and Electrostatic Discharge (ESD) Tests - In Compliance Magazine | Q29: 😮
B32: Objective 2: Knowing your extension board (OLED1) (you can get help by opening User Guide for OLED1 Xplained PRO)
B33: DO NOT CONNECT the extension board to the main board yet!!! Follow the exercises!!!
B34: 🥇 | C34: =COUNTIF(D36:D41,TRUE)/COUNT(C36:C41) -> 0 | E34: =IFERROR(__xludf.DUMMYFUNCTION("SPARKLINE(C34,{""charttype"",""bar"";""max"",1;""min"",0;""color1"",IF(C34>0.75,""green"",IF(C34>0.5,""yellow"",""red""))})"),"")
C36: 121 | D36: FALSE | E36: Search and identify OLED display.
C37: 122 | D37: FALSE | E37: Search and identify LED1, LED2 and LED3 that you will program to lit.
C38: 123 | D38: FALSE | E38: Search and identify BUTTON 1, BUTTON 2 and BUTTON 3.
C39: 124 | D39: FALSE | E39: Search and identify the extension header.
C40: 125 | D40: FALSE | E40: Search and identify GND and VCC pin on the header.
C41: 126 | D41: FALSE | E41: Now, follow this 3-steps procedure: (1) unplug the USB cable from PC/laptop!!! (2) connect OLED1
E42: board to EXT1 header from the main board and (3) finally reconnect the USB cable to the PC/laptop.
E43: You must ALWAYS follow this procedure when you want to connect something to the main board!
B45: Objective 3: Knowing your extension board (IO1) (you can get help by opening User Guide for IO1 Xplained PRO)
B46: DO NOT CONNECT the extension board to the main board yet!!! Follow the exercises!!!
B47: 🥇 | C47: =COUNTIF(D49:D56,TRUE)/COUNT(C49:C56) -> 0 | E47: =IFERROR(__xludf.DUMMYFUNCTION("SPARKLINE(C47,{""charttype"",""bar"";""max"",1;""min"",0;""color1"",IF(C47>0.75,""green"",IF(C47>0.5,""yellow"",""red""))})"),"")
C49: 131 | D49: FALSE | E49: Search and identify the light sensor.
...

Sheet W1-part2
B1: MARQUARDT SUMMER INTERNSHIP 2024
B2: GOAL FOR THIS WEEK 2: Design a good software program for controlling LEDs and buttons | K2: =SUM(C12,C36,C71,C89,C150,C169)/6 -> 0 | M2: =COUNTIF(L13:L225,TRUE)/O2 -> 0 | N2: of | O2: =SUM(COUNTIF(L13:L225,TRUE),COUNTIF(L13:L225,FALSE)) -> 6 | P2: additional materials
C3: By the end of this week you should be able to control basic elements of every embedded system: LEDs and buttons.
C4: Personal programming style/performance should be acknowledged and improved (comments, clarity, modularity).
C5: On short what you will do this week:
D6: - get to control some LEDs
D7: - use generalization, modular programming and other software design principles to improve your coding style/performance
D8: - use polling to read buttons
B11: Objective 1: Turn on user LED0
B12: 🥇 | C12: =(COUNTIF(D14:D31,TRUE))/COUNT(C14:C31) -> 0 | E12: =IFERROR(__xludf.DUMMYFUNCTION("SPARKLINE(C12,{""charttype"",""bar"";""max"",1;""min"",0;""color1"",IF(C12>0.75,""green"",IF(C12>0.5,""yellow"",""red""))})"),"")
C14: 211 | D14: FALSE | E14: Clean your main.c file and include the header file iom324pb.h using include directive (#include). The
E15: function main( ) should be of type void and it has no return statement because it is never returning! Compared to PC
E16: software program, the embedded software program has this unique characteristic: it is stuck | M16: FOR YOUR INFO | P16: 🔊
E17: in an infinite while(1) loop. Intentionally!!! Therefore your program must have this loop also. | M17: Explore how microcontrollers work here:
L18: FALSE | M18: Exploring How Computers Work - YouTube
C19: 212 | D19: FALSE | E19: How many pins does the PORTC port have? | I19: (<<< your answer here)
C20: 213 | D20: FALSE | E20: How many GPIO (General Purpose Input Output) ports does the ATmega324PB microcontroller
E21: have in total? | I21: (<<< your answer here)
C23: 214 | D23: FALSE | E23: Search in the dev board User Guide the port and the pin to which LED0 is connected and how you
E24: should light up (or activate) LED0. Read carefully, repeatedly (maybe 10x), see if you really understand that information.
E25: You can correlate with the information from electronic schematic of our dev board.
E26: See if the all these information match in your mind with the general knowledge on LEDs control acquired last week.
E27: Further correlate with microcontroller datasheet on how to configure the pins (chapter 16.2.1).
C28: 215 | D28: FALSE | E28: Write a program code for light up the LED0. You need to take control over the registers implied in turning LED0 on.
E29: Compile and download the code.
E30: Run the code in order to see LED0 on. Congrats! | H30: 👏👏👏
C31: 216 | D31: FALSE | E31: Program LED0 to be turned on for 1 second*, turned off for the next 1 second and so on (repeat the sequence).
E32: *Note: for the LED0 to stay 1 second turned on you will need to use a time delay. We are calling it software delay.
E33: A software delay can be build using a for loop big enough to count for 1 second.
B35: Objective 2: Turn on external LEDs
B36: 🥇 | C36: =COUNTIF(D38:D58,TRUE)/COUNT(C38:C58) -> 0 | E36: =IFERROR(__xludf.DUMMYFUNCTION("SPARKLINE(C36,{""charttype"",""bar"";""max"",1;""min"",0;""color1"",IF(C36>0.75,""green"",IF(C36>0.5,""yellow"",""red""))})"),"")
C38: 221 | D38: FALSE | E38: Check the electronic schematic of the ATMega324PB development board. Is there any resistor
E39: connected with the integrated LED0 in order to protect it? What value has that resistor?
G40: ( <<< resistor value here ) | M40: FOR YOUR INFO | P40: 🔊
M41: Explore how LEDs are working:
C42: 222 | D42: FALSE | E42: In Reference_Documents folder you find the electronic schematics for OLED1 and IO1 boards (check .zip files). | L42: FALSE | M42: Light-Emitting Diodes (LEDs) - SparkFun Learn
E43: Can you figure it out, just by reading the schematics (NOT the User Guide!!!), how to turn on | M43: How to work with bitmasks
E44: the contained LEDs for each board? | L44: FALSE | M44: What are Bit Masks, and how do I use them?
C45: 223 | D45: FALSE | E45: Check that OLED1 extension board is connected to EXT1 header. Program all 3 LEDs to be turned on at once.
E46: Double check(!) with User Guide for OLED1 to see if schematics information matches with regards to LEDs activation.
...

Sheet W2-part1
B1: MARQUARDT SUMMER INTERNSHIP 2024
B2: GOAL FOR THIS WEEK 3: Interrupts and Analog-to-Digital conversions | K2: =SUM(C13,C64,C89,C113,C148,C220)/6 -> 0 | O2: =COUNTIF(N13:N221,TRUE)/Q2 -> 0 | P2: of | Q2: =SUM(COUNTIF(N13:N221,TRUE),COUNTIF(N13:N221,FALSE)) -> 8 | R2: additional materials
C3: By the end of this week you should be able to handle the interrupts and an AD conversion.
C4: Personal programming style/performance should be acknowledged and improved further (coding rules and naming conventions).
C5: On short what you will do this week:
D6: - get to control buttons by interrupts
D7: - redesign you code respecting some basic naming conventions/rules
D8: - build a main application: CONTROL PANEL
D9: - control the ADC and light sensor
B12: Objective 1: "Hello" interrupts!
B13: 🥇 | C13: =COUNTIF(D15:D61,TRUE)/COUNT(C15:C61) -> 0 | E13: =IFERROR(__xludf.DUMMYFUNCTION("SPARKLINE(C13,{""charttype"",""bar"";""max"",1;""min"",0;""color1"",IF(C13>0.75,""green"",IF(C13>0.5,""yellow"",""red""))})"),"")
C15: 311 | D15: FALSE | E15: With this objective we introduce the interrupts, THE big idea in embedded systems :)
E16: A microcontroller can implement many sources/triggers of interrupts for its processor (CPU). One simple interrupt
E17: can be the one triggered by the push of an external button. So you push the button and a signal is sent | O17: FOR YOUR INFO | S17: 🔊
E18: through the registers way up until it reaches the CPU. That signal is the interrupt request. Keep in mind this short idea, | N18: FALSE | O18: External Interrupts - SPARK FUN on YouTube
E19: button pressed > pin voltage level changed > interrupt request to CPU, when studying from the microcontroller's | N19: FALSE | O19: Learning AVR-C Episode 9: External Interrupts - YouTube
E20: datasheet the interrupts for your personal understanding. Be aware you will encounter a lot of information noise, but you
E21: have to filter it out... so keep focus on what you have to find to program the interrupts triggered by your button press.
E22: Study: | J22: =COUNTIF(J23:J29,TRUE)/7 -> 0
E23: - chapter 8.1 on how interrupts are implemented.............................................. | J23: FALSE
E24: - chapter 8.3.1 on the Global Interrupt Enable bit effect.................................... | J24: FALSE
E25: - chapter 8.5 on the link between Stack Pointer and interrupts.......................... | J25: FALSE
E26: - chapter 8.8 and down the page chapter 8.8.1 on the behavior of interrupts.... | J26: FALSE
E27: - chapter 14.1 on the Interrupt Vector Table (just the table!!!) ............................. | J27: FALSE
E28: - chapter 15 on the external interrupts mechanism and registers description... | J28: FALSE
E29: - chapter 6 table for pin identification................................................................... | J29: FALSE
C31: 312 | D31: FALSE | E31: Identify and double check within iom324pb.h that the interrupt vector table is implemented correctly.
E32: Go to Compiler Guide (from IAR Embedded Workbench HELP) and read for: | K32: =COUNTIF(K33:K35,TRUE)/3 -> 0
E33: - INTERRUPT FUNCTIONS (pag.64)........................................................................................................ | K33: FALSE
E34: - RESTRICTIONS FOR SPECIAL FUNCTION TYPES => Interrupt functions (pag.163)........................... | K34: FALSE
E35: - __interrupt keyword (pag. 307)................................................................................................................. | K35: FALSE
C37: 313 | D37: FALSE | E37: As your understanding over interrupts grows it is time to introduce the routine executed by the CPU when it will be
E38: interrupted by the external request. So remember the sequence:
E40: button pressed > pin voltage level changed > interrupt request to CPU > jump to vector > executes routine written by you
E42: Our IAR compiler (like any other compiler) uses a special construct to mark the function written by you in C language
E43: as being the routine executed by the CPU in case of interrupt request. Remember that saying it is a FUNCTION
E44: is improper/wrong, the correct saying is INTERRUPT SERVICE ROUTINE, on short ISR. It is a routine and not
E45: a function for some simple reasons: it does not have input parameters, does not return anything and it is not called (!!!)
E46: like a normal function is called within the program. The amount of code you write inside ISR should be kept small.
E47: Below is an example of what you should write (between #pragma and the ISR name you MUST NOT
...

Sheet W2-part2
B1: MARQUARDT SUMMER INTERNSHIP 2023
B2: GOAL FOR THIS WEEK 4: Tack your app with TIMERS | K2: =SUM(C10,C82,C140,C189,C206)/5 -> 0 | M2: =COUNTIF(M71:M249,TRUE)/4 -> 0 | N2: of additional materials [ 4 ]
C3: By the end of this week you should be able to control the TC0 peripheral to measure time.
C4: On short what you will do this week:
D5: - get to setup and control TC0
D6: - measure timings and output pin signals accordingly
B9: Objective | D9: 1 | E9: Getting to know TC0 timer
B10: 🥇 | C10: =(COUNTIF(D12:D60,TRUE))/2 -> 0 | E10: =IFERROR(__xludf.DUMMYFUNCTION("SPARKLINE(C10,{""charttype"",""bar"";""max"",1;""min"",0;""color1"",IF(C10>0.75,""green"",IF(C10>0.5,""yellow"",""red""))})"),"")
C12: 411 | D12: FALSE | E12: Go at the top menu bar: Atmel-ICE -> Fuse Handler -> Low Fuse -> check the box: Divide clock by 8 internally, check the box: Clock output on PORTB1
E13: Select from the drop-down list the Internal RC oscillator 8MHz as shown (the New Value for Low Fuse si 0x22) -> Program Fuses -> Close.
E36: What you have set here is the source for system clock signal. The heartbeat of the system. Internal RC oscillator @ 8MHz frequency, but divided by 8, so
E37: resulting in 1MHz system clock frequency which will be distributed to all peripherals including CPU (as shown below).
E38: Lowering the system clock frequency is a great way to reduce power consumption in embedded systems.
E58: TC0 is an 8bit timer/counter which also receives clock signal from this source (as shown). This TC0 we will study further.
C60: 412 | D60: FALSE | E60: TC0 is on chapter 17 in datasheet. REMEMBER:
E61: Every time you need to work with a peripheral module: | I61: =COUNTIF(E62:E73,TRUE)/8 -> 0
E62: FALSE | F62: -1- you will encounter a lot of information noise, so prepare your mind to filter
E63: FALSE | F63: -2- you will not understand all the information at once, therefore be patient reading 2x, 3x times
E64: FALSE | F64: -3- start with the block diagram; it shows in a simplified manner the overall dynamics of that peripheral; follow
F65: the signals from outside of the capsule via pins to the inside (and/or viceversa) and further to databus along sketched lines;
F66: look also for what clock source has and if interrupt request lines are present there to send interrupt signals to CPU
E67: FALSE | F67: -4- read the overview (with observation 1&2&3 in mind :)
E68: FALSE | F68: -5- check how many registers that peripheral has (to limit your anxiety over the problem)
E69: FALSE | F69: -6- hover the registers description once scanning with your eyes about how can you implement the objective you have in mind (e.g.
F70: for ADC you will want to obtain a digital converted value and use it further, for TIMERS you will want to obtain periodic interrupts, etc.)
E71: FALSE | F71: -7- read the registers description second time looking for how to enable the peripheral, how are you making use of
F72: its functionality and its final result*, how you will work with interrupt requests (if you decide to work with interrupts)
E73: FALSE | F73: -8- read the registers description third time looking to take THE EASIEST decisions over the settings of each bit** (!!!) even if
F74: that means not to modify their default (after reset) value at all (this is a valid decision also, right? :); this is the point
F75: where you should go also to chapters describing the functionalities (e.g. normal mode, etc.) to get more clarifications.
N76: FOR YOUR INFO | O76: 🔊
E77: Note*: in TC0 case the final result will depend on the Operating Mode you choose (in Normal mode final result is interrupt request to CPU at overflow, | M77: FALSE | N77: Introduction to AVR Timers » maxEmbedded
E78: in CTC mode the final result will be an interrupt request to CPU when matching occurs, in PWM mode the final result | M78: FALSE | N78: AVR Timer programming - Tutorials (exploreembedded.com)
E79: will be a digital signal output to physical microcontroller's pin). The following exercises will guide you through. | M79: FALSE | N79: AVR130: Setup and Use of AVR Timers (microchip.com)
B81: Objective | D81: 2 | E81: Start simple: NORMAL MODE of operation for TC0
B82: 🥇 | C82: =(COUNTIF(D84:D114,TRUE)+COUNTIF(D127:AD136,TRUE))/8 -> 0 | E82: =IFERROR(__xludf.DUMMYFUNCTION("SPARKLINE(C82,{""charttype"",""bar"";""max"",1;""min"",0;""color1"",IF(C82>0.75,""green"",IF(C82>0.5,""yellow"",""red""))})"),"")
C84: 421 | D84: FALSE | E84: Your big task now is to make TC0 work in NORMAL MODE (from 0x00 to 0xFF) obtaining an interrupt at overflow.
E86: After reading the TC0 datasheet information (registers & functionalities) you should have these questions.
E87: Note**: Here you can find some good start decisions:
E89: Register | F89: Questions | I89: Good start decisions
...

Sheet W3-part1
B1: MARQUARDT SUMMER INTERNSHIP 2023
B2: GOAL FOR THIS WEEK 5: Build a task scheduler | K2: =SUM(C10,C59,C103,C119)/4 -> 0 | M2: =COUNTIF(M58:M99,TRUE)/4 -> 0 | N2: of additional materials [ 0 ]
C3: By the end of this week you should be able to understand and implement processor time scheduling.
C4: On short what you will do this week:
D5: - use TC0 to build a scheduling algorithm
D6: - design your application with task/function scheduling perspective
B9: Objective | D9: 1 | E9: Building from scratch a TASK SCHEDULER
B10: 🥇 | C10: =(COUNTIF(D12:D47,TRUE))/5 -> 0 | E10: =IFERROR(__xludf.DUMMYFUNCTION("SPARKLINE(C10,{""charttype"",""bar"";""max"",1;""min"",0;""color1"",IF(C10>0.75,""green"",IF(C10>0.5,""yellow"",""red""))})"),"")
C12: 511 | D12: FALSE | E12: First we relied on the while(1) loop to make the CPU go through our functions calls and execute those functions.
E13: Then we added interrupts, forcing the CPU to respond to events with routines execution.
E14: We had no concern about the "time" the CPU is spending with a particular function execution.
E15: A task scheduler is about that: taking care of CPU spent time on functions execution.
E16: Because "CPU time" is a resource, we would like to share this resource cooperatively among the functions from our program.
E17: Therefore we allocate a "time slot" or "time slice" for each function. Time slot/slice is the time passed between two consecutive timer interrupts.
E18: Time slots are periodic as timer interrupts are periodic. So each function has its CPU execution between two timer interrupts.
E19: How you trigger the execution of a function? Allocate a flag for each function and activate that flag for the time slot you want the execution to happen.
E20: Flags are activated within the ISR. This selective activation of flags is called flags management and it's similar to what you exercised last week by
E21: extending real time measurements beyond the maximum timings TC0 could provide.
E22: One more thing remains to do before scheduling is complete: looping through the flags and check if they are activated. If yes, then it's time to call
E23: that particular function to which this time slice has been allocated.
E24: At its core, a task scheduler consists of:
... E27: 3. tasks dispatcher
C29: 512 | D29: FALSE | E29: System Tick
E30: Choose a timer that will be dedicated to construct the system tick, e.g. TC0 or TC1. Set the timer for interrupts at 10ms precise interval.
E31: ATTENTION! in order for you to obtain the most accurate 10ms interval you have to research what is the best setup. So, play around with:
E32: => | F32: the initial settings for oscillator (uncheck the option "Divide clock by 8 internally" and/or choose external oscillator)
E33: => | F33: the 8bit vs. 16bit timers
E34: Remember that you are looking for the smallest deviation/offset from the 10ms mark...... and make a final decision!
E35: Now you have an accurate system tick. As file organization is concerned, this interrupt service routine should be placed in the corresponding timer module.
E36: The timer you choose will remain dedicated to do the scheduling and you cannot use it for something else in your program.
C37: 513 | D37: FALSE | E37: Flags Manager
E38: Starting with 10ms period build other longer periods of time: 50ms, 100ms, 500ms, 1000ms. Dedicate flag variables for each period.
E39: Optionally you can add more periods. You can gather all these into a single function, e.g. void scheduler_flags_management (void).
E40: Call it from within the ISR.
E41: As file organization is concerned, this flags management function should be placed in scheduler module.
C42: 514 | D42: FALSE | E42: Tasks Dispatcher
E43: Inside the while(1) loop you will check for the flags associated to the defined time slots and if they are set, then the associated function will be called.
E44: After the call, that particular flag must be reset in order to avoid the second call of the same function per current time slice when while(1) is re-entered.
E45: The final result of these constructs will be that each function call is time-spaced apart by a time slice of 10ms. Precisely! What a schedule!!!
E46: It is a cooperative schedule because functions are not prioritized, they do not interrupt each other. | K46: 👏👏👏
...

Sheet W3-part2
B1: MARQUARDT SPRING INTERNSHIP 2023
B2: GOAL FOR THIS WEEK 6: Fine tunning with PWM and State Machines | K2: =SUM(C11,C19,C44,C71,C128,C200,C214,C304)/8 -> 0 | M2: =COUNTIF(M18:M67,TRUE)/4 -> 0 | N2: of additional materials [ 0 ]
C3: By the end of this week you should be able to understand and implement PULSE WIDTH MODULATION + STATE MACHINES.
C4: On short what you will do this week:
D5: - use TC0/TC1 to build PWM signals
D6: - control the brightness of LEDs with PWM
D7: - understand and use the concept of state machines
B10: Objective | D10: 1 | E10: Understanding PWM signals
B11: 🥇 | C11: =(COUNTIF(D13:D16,TRUE))/4 -> 0 | E11: =IFERROR(__xludf.DUMMYFUNCTION("SPARKLINE(C11,{""charttype"",""bar"";""max"",1;""min"",0;""color1"",IF(C11>0.75,""green"",IF(C11>0.5,""yellow"",""red""))})"),"")
C13: 611 | D13: FALSE | E13: PWM attributes
C14: 612 | D14: FALSE | E14: How PWM works
C15: 613 | D15: FALSE | E15: PWM with AVR timers explained
C16: 614 | D16: FALSE | E16: An example with PWM
B18: Objective | D18: 2 | E18: Fast PWM MODE of operation for TC0
B19: 🥇 | C19: =(COUNTIF(D21:D41,TRUE))/6 -> 0 | E19: =IFERROR(__xludf.DUMMYFUNCTION("SPARKLINE(C19,{""charttype"",""bar"";""max"",1;""min"",0;""color1"",IF(C19>0.75,""green"",IF(C19>0.5,""yellow"",""red""))})"),"")
C21: 621 | D21: FALSE | E21: The Fast PWM is an operating mode of TC0 timer.
E22: Having already some experience with ADC operation and Normal/CTC modes of operation for TC0, you are now able to study chapter 17 in the
E23: datasheet, looking for Fast PWM Mode. You should apply the same 8 identified steps as for the aforementioned operations.
C24: 622 | D24: FALSE | E24: Check on the boards (user guides, schematics) to what pins you can output a PWM signal and if those pins have LEDs connected !!!
E25: Not all pins can support/output PWM signals.
C26: 623 | D26: FALSE | E26: Construct a new module for PWM feature containing the appropriate functions (remember: initialization, atomic actions, etc...)
E27: Do the math for implementing into one single function the following 5 use cases with PWM:
F28: - output a PWM signal with 100% duty cycle
F29: - output a PWM signal with 75% duty cycle
F30: - output a PWM signal with 50% duty cycle
F31: - output a PWM signal with 25% duty cycle
F32: - output a PWM signal with 0% duty cycle
E33: Individually apply each case to the LED identified as supporting PWM.
C35: 624 | D35: FALSE | E35: Having the Task Scheduler as your best friend (!) design an application where you incrementally apply these use cases to the LED identified
E36: as supporting PWM.
E37: e.g. you can apply the signal in an incremental way: on the first run of 10ms task you apply 0% duty cycle, on the second you apply 25% duty cycle,
E38: on the third 50%, and so on and so forth, then start all over again.
C39: 625 | D39: FALSE | E39: What is the duty cycle resolution of the PWM signals (=the smallest duty cycle % step you can increment with) that can be build on TC0 ?
E40: Number of steps: | G40: (<<< answer here) | I40: Step size (resolution in %): | L40: (<<< answer here)
C41: 626 | D41: FALSE | E41: Add a new feature to your PWM driver: the possibility to change the duty-cycle with 1% step size. You would build a new provided interface e.g. void pwm_dc(int param);
B43: Objective | D43: 3 | E43: Complex behaviors
B44: 🥇 | C44: =(COUNTIF(D46:D56,TRUE))/2 -> 0 | E44: =IFERROR(__xludf.DUMMYFUNCTION("SPARKLINE(C44,{""charttype"",""bar"";""max"",1;""min"",0;""color1"",IF(C44>0.75,""green"",IF(C44>0.5,""yellow"",""red""))})"),"")
C46: 631 | D46: FALSE | E46: Build the next behavior for the LED identified as supporting PWM. The sequence described will be repetitive with pause (=PWM duty cycle 0%) of 3s.
E47: Be very attentive as the graphic below shows not the duty-cycle of a PWM signal, but the variation (!!!) of the PWM duty-cycle across time.
E48: The duty-cycle resolution you choose for ramping up PWM from 0% to 100% is up-to-you.
...

Sheet W3-part3
B1: MARQUARDT SUMMER INTERNSHIP 2024
B2: GOAL FOR THIS WEEK 2 - part 2: UART Serial Communication | K2: =SUM(C10,C29,C50,C58)/4 -> 0 | M2: =COUNTIF(M28:M84,TRUE)/4 -> 0 | N2: of additional materials [ 0 ]
C3: By the end of this week you should be able to design and implement a serial communication.
C4: On short what you will do this week:
D5: - understand the concept of serial communication
D6: - apply the concept of serial communication to your application
B9: Objective | D9: 1 | E9: Understanding Serial Communication
B10: 🥇 | C10: =(COUNTIF(D12:D23,TRUE))/8 -> 0 | E10: =IFERROR(__xludf.DUMMYFUNCTION("SPARKLINE(C10,{""charttype"",""bar"";""max"",1;""min"",0;""color1"",IF(C10>0.75,""green"",IF(C10>0.5,""yellow"",""red""))})"),"")
C12: 711 | D12: FALSE | E12: Understanding Serial Protocols - YouTube
C13: 712 | D13: FALSE | E13: Understanding UART - YouTube
C14: 713 | D14: FALSE | E14: PROTOCOLS: UART - I2C - SPI - Serial communications #001 - YouTube
C15: 714 | D15: FALSE | E15: UART (Universal Asynchronous Receiver Transmitter) - Basics - YouTube
C16: 715 | D16: FALSE | E16: UART - Troubleshooting tips (Debugging UART issues) - YouTube
C17: 716 | D17: FALSE | E17: Tutorials for the AVR Microcontroller : UART
C18: 717 | D18: FALSE | E18: FOR YOUR INFORMATION: RS-232 is a very similar serial protocol to UART (it is similar because in its simplest form has the same hardware connections and uses the
E19: UART frame definition, but voltage levels are very different). It is used today mainly for industrial applications. Also your PC could still have the DB9 connector for RS-232.
E20: Serial Ports Are STILL Around! - YouTube
E21: Serial Ports - YouTube
E22: Control LEDs with your computer using RS232! - YouTube
C23: 718 | D23: FALSE | E23: FOR YOUR INFORMATION: Inside your car there is LIN serial communication protocol which uses the UART hardware connections, frame definition and voltage levels.
E24: However, the number of frames, their sequence and the meaning of data sent with the frames is what makes LIN a new protocol on top of UART definitions.
E25: Marquardt develops products based on LIN protocol.
E26: LIN Message Frame - Developer Help (microchipdeveloper.com)
B28: Objective | D28: 2 | E28: Setting up the USART
B29: 🥇 | C29: =(COUNTIF(D31:D44,TRUE))/4 -> 0 | E29: =IFERROR(__xludf.DUMMYFUNCTION("SPARKLINE(C29,{""charttype"",""bar"";""max"",1;""min"",0;""color1"",IF(C29>0.75,""green"",IF(C29>0.5,""yellow"",""red""))})"),"")
C31: 721 | D31: FALSE | E31: First, observe that for our microcontroller the naming is not UART (as general accepted) but USART. The letter S comes from a feature enhancement of this peripheral:
E32: the engineers have decided to add a clock line, transforming the asynchronous UART into a synchronous one. The synchronous communication is not an UART anymore
E33: but an SPI (Serial Peripheral Interface) using the same hardware with UART. You can look at this enhacement as two mutual exclusive modes of operations of the same
E34: USART hardware module. We will not use the synchonous mode, therefore we will implement an asynchronous UART communication using the USART periferal.
E35: For the sake of consistency we will keep the datasheet naming only for the peripheral references and the register names, but use UART name every time we refer
E36: to the communication protocol.
C37: 722 | D37: FALSE | E37: To implement a simple UART communication we will use the IO1 board.
E38: Observe that on the IO1 board there is a black jumper which connects the TX and RX of the same USART peripheral (e.g. USART0). This connection is called loopback.
E39: We will use those TX, RX connected together to simulate the communication between two different microcontrollers. Imagine that TX is from MCU1 sending messages
E40: and RX is from MCU2 receiving the messages. This is a simplex communication (one way communication, as MCU2 will not be able to respond back to MCU1,
E41: because RX pin cannot transmit, it only receives, but that's ok for our purpose here).
C42: 723 | D42: FALSE | E42: Identify (using schematics and User Guides) the exact peripheral name which has the TX, RX exposed on IO1. Is it USART0, USART1 or USART2?
F43: (<<< answer here)
C44: 724 | D44: FALSE | E44: Use the same approach as you had for ADC and TIMER peripherals to study the datasheet chapter for USART peripheral. Observe there is a chapter also dedicated
E45: to the USART in SPI mode which we will NOT use.
...
